Workbook
Name _ftn1: OVERVIEW!$B$14
Name _ftnref1: OVERVIEW!$B$5
Name _Hlk135037178: LEARNERS!$F$968
Name _Hlk135910797: LEARNERS!$B$439
Name _Hlk136271606: LEARNERS!$I$625
Name _Hlk136526796: 'SCHOOL NUTRITION'!$B$14
Name _Toc135070642: OVERVIEW!$B$4
Name _Toc137742947: 'SCHOOL INFRASTRUCTURE'!$B$496
Name _Toc137743006: 'SCHOOL INFRASTRUCTURE'!$B$99
Name _Toc137743007: 'SCHOOL INFRASTRUCTURE'!$B$111
Name _Toc137743008: 'SCHOOL INFRASTRUCTURE'!$B$123
Name _Toc137743009: 'SCHOOL INFRASTRUCTURE'!$B$135
Name _Toc137743010: 'SCHOOL INFRASTRUCTURE'!$B$147
Name _Toc137743012: 'SCHOOL INFRASTRUCTURE'!$B$174
Name _Toc137743014: 'SCHOOL INFRASTRUCTURE'!$B$214
Name _Toc137743015: 'SCHOOL INFRASTRUCTURE'!$B$234
Name _Toc137743016: 'SCHOOL INFRASTRUCTURE'!$B$254
Name _Toc137743017: 'SCHOOL INFRASTRUCTURE'!$B$298
Name _Toc137743018: 'SCHOOL INFRASTRUCTURE'!$B$310
Name _Toc137743020: 'SCHOOL INFRASTRUCTURE'!$B$334
Name _Toc137743022: 'SCHOOL INFRASTRUCTURE'!$B$364
Name _Toc137743024: 'SCHOOL INFRASTRUCTURE'!$B$394
Name _Toc137743025: 'SCHOOL INFRASTRUCTURE'!$B$406
Name _Toc137743026: 'SCHOOL INFRASTRUCTURE'!$B$424
Name _Toc137743028: 'SCHOOL INFRASTRUCTURE'!$B$448
Name _Toc137743030: 'SCHOOL INFRASTRUCTURE'!$B$472
Name _Toc137743032: 'SCHOOL INFRASTRUCTURE'!$B$498
Name _Toc137743033: 'SCHOOL INFRASTRUCTURE'!$B$520
Name _Toc137743034: LEARNERS!$B$6
Name _Toc137743035: LEARNERS!$B$24
Name _Toc137743036: LEARNERS!$B$45
Name _Toc137743039: LEARNERS!$B$99
Name _Toc137743040: LEARNERS!$B$117
Name _Toc137743042: LEARNERS!$B$152
Name _Toc137743043: LEARNERS!$B$171
Name _Toc137743045: LEARNERS!$B$209
Name _Toc137743046: LEARNERS!$B$229
Name _Toc137743047: LEARNERS!$B$251
Name _Toc137743048: LEARNERS!$B$251
Name _Toc137743049: LEARNERS!$B$277
Name _Toc137743050: LEARNERS!$B$298
Name _Toc137743052: LEARNERS!$B$358
Name _Toc137743055: LEARNERS!$B$426
Name _Toc137743056: LEARNERS!$B$455
Name _Toc137743058: LEARNERS!$B$489
Name _Toc137743059: LEARNERS!$B$504
Name _Toc137743063: LEARNERS!$B$578
Name _Toc137743064: LEARNERS!$B$591
Name _Toc137743066: LEARNERS!$B$619
Name _Toc137743073: LEARNERS!$B$703
Name _Toc137743074: LEARNERS!$B$716
Name _Toc137743090: LEARNERS!$B$927
Name _Toc137743092: LEARNERS!$B$953
Name _Toc137743094: LEARNERS!$B$985
Name _Toc137743095: LEARNERS!$B$1000
Name _Toc137743096: LEARNERS!$B$1015
Name _Toc137743098: LEARNERS!$B$1045
Name _Toc137743099: LEARNERS!$B$1060
Name _Toc137743100: LEARNERS!$B$1073
Name _Toc137743102: LEARNERS!$B$1101

Sheet TABLE OF CONTENTS
B3: TABLE OF CONTENTS
B5: GENERAL OVERVIEW
C6: =OVERVIEW!$B$4 -> Overview 1: Number of schools by level of education
C7: =OVERVIEW!$B$16 -> Overview 2: Number of classrooms in use
C8: =OVERVIEW!$B$27 -> Overview 3: Number of learners
C9: =OVERVIEW!$B$51 -> Overview 4: Number of teaching and administrative staff
B11: 1. SCHOOL INFRASTRUCTURE
C12: 1.1 Number of schools by levels of education and schools’ settings
D13: Table 1.1.1: Number of schools by level of education
D14: Table 1.1.2: Number of preprimary, primary, secondary and TVET L1-L5 schools
D15: Table 1.1.3: School settings with preprimary level
D16: Table 1.1.4: School settings with primary level
D17: Table 1.1.5: School settings with General and professional secondary
D18: Table 1.1.6: School settings with TVET L1 to L5
C19: 1.2 Number of schools by schools’ status
D20: Table 1.2.2: Number of Schools with Pre-primary level, by schools’ status
D21: Table 1.2.3: Number of schools with Primary level by school’ status
D22: Table 1.2.4: Number of schools with gen. and prof. secondary Level, by school’ status
D23: Table 1.2.5: Number of schools with TVET L1 to L5, by school’ status
D24: Table 1.2.6: Number of Higher education institutions
D25: Table 1.2.7: Number of adult literacy centers
C26: 1.3 Number of schools by owner
D27: Table 1.3.1: Number of schools with preprimary level by owner
D28: Table 1.3.2: Number of schools with primary level by owner
D29: Table 1.3.3: Number of Gen. and prof. secondary schools by owner
D30: Table 1.3.4: Number of schools with TVET level by owner
D31: Table 1.3.5: Number of adult literacy centers by owner
D32: Table 1.3.6: Number and Percentage of schools meeting the Standard PCR
D33: Table 1.3.7: Availability of girls’ room
C34: 1.4 Classrooms in use and classes in school
D35: Table 1.4.1: Total number of classrooms in use, by schools ‘status
D36: Table 1.4.2: Number of Preprimary classrooms, by schools 'status
D37: Table 1.4.3 : Number of primary classrooms in use by school status
D38: Table 1.4.4: Number of primary school classes by school status
D39: Table 1.4.5: Number of primary classrooms in use per grade
D40: Table 1.4.6: Number of gen. and prof. secondary classrooms in use
D41: Table 1.4.7: Number of gen. and prof. secondary classrooms per grade
D42: Table 1.4.8: Number of TVET classrooms for level I to 5
D43: Table 1.4.9: Number of TVET’ classrooms per level
C44: 1.5 Number of desks in school
...

Sheet OVERVIEW
B2: GENERAL OVERVIEW
B4: Overview 1: Number of schools by level of education
B5: Schools* | C5: 2021/22 | D5: 2022/23
B6: Schools with Preprimary level | C6: 3808 | D6: 4051
B7: Schools with Primary level | C7: 3831 | D7: 3932
B8: Schools with General and professional secondary level | C8: 1955 | D8: 1977
B9: Schools with TVET L1_L5 | C9: 422 | D9: 470
B10: Polytechnics | C10: 8 | D10: 8
B11: General Higher education | C11: 31 | D11: 32
B12: Adult Literacy | C12: 5076 | D12: 5003
B13: Source: School census, Ministry of Education
B14: *Caution should be taken for not summing up number of schools in this table, because one school can have different levels.
B16: Overview 2: Number of classrooms in use
B17: Levels | C17: 2021/22 | D17: 2022/23
B18: Preprimary | C18: 8358 | D18: 10726
B19: Primary | C19: 46010 | D19: 49561
B20: Lower secondary | C20: 12783 | D20: 13189
B21: General and professional upper secondary | C21: 7182 | D21: 7506
B22: TVET L1_L2 | C22: 536 | D22: 533
B23: TVET L3_L5 | C23: 2760 | D23: 3220
B24: Total | C24: 77629 | D24: =SUM(D18:D23) -> 84735
B25: Source: School census, Ministry of Education
B27: Overview 3: Number of learners
B28: Levels of education | C28: 2021/22 | D28: 2022/23
B29: Preprimary | C29: 355325 | D29: 540998
B30: Primary | C30: 2742901 | D30: 2838343
B31: Lower Secondary | C31: 540671 | D31: 536427
B32: Upper secondary | C32: 259822 | D32: 283287
B33: General upper secondary | C33: 168595 | D33: 170399
B34: Sciences | C34: 99630 | D34: 104668
B35: Humanities | C35: 32671 | D35: 33943
B36: Languages | C36: 36294 | D36: 31788
B37: Professional upper secondary | C37: 21065 | D37: 23172
B38: TTC | C38: 11565 | D38: 12701
B39: Nursing | C39: 209 | D39: 657
B40: Accounting | C40: 9291 | D40: 9814
... B48: Total learners in Rwanda | C48: 4159782 | D48: 4456419
B49: Source: School census, Ministry of Education
B51: Overview 4: Number of teaching and administrative staff
B52: Levels | C52: 2021/22 | D52: 2022/23
...

Sheet SCHOOL INFRASTRUCTURE
B2: 1. SCHOOL INFRASTRUCTURE
B4: 1.1 Number of schools by levels of education and schools’ settings
B6: Table 1.1.1: Number of schools by level of education
B7: Levels of education | C7: 2017 | D7: 2018 | E7: 2019 | F7: 2020/21 | G7: 2021/22 | H7: 2022/23
B8: Overall number of schools* | C8: 4719 | D8: 4571 | E8: 4706 | F8: 5144 | G8: 4842 | H8: 4923
B9: Schools with Preprimary level | C9: 3186 | D9: 3210 | E9: 3401 | F9: 3741 | G9: 3808 | H9: 4051
B10: Schools with Primary level | C10: 2877 | D10: 2909 | E10: 2961 | F10: 3691 | G10: 3831 | H10: 3932
B11: Schools with General and professional Secondary level | C11: 1567 | D11: 1416 | E11: 1452 | F11: 1869 | G11: 1955 | H11: 1977
B12: Schools with TVET L1-L5 level | C12: 385 | D12: 350 | E12: 331 | F12: 344 | G12: 422 | H12: 470
B13: Polytechnics | C13: 17 | D13: 10 | E13: 10 | F13: 8 | G13: 8 | H13: 8
B14: General Higher education | C14: 37 | D14: 30 | E14: 30 | F14: 30 | G14: 31 | H14: 32
B15: Adult literacy | C15: 5160 | D15: 4991 | E15: 5194 | F15: 4953 | G15: 5076 | H15: 5003
B16: Source: School census, Ministry of Education and ECDs censu
B17: *Preprimary, Primary, secondary and TVET L1 to L5 schools
B19: Table 1.1.2: Number of preprimary, primary, secondary and TVET schools by settings
B20: Settings* | C20: 2017 | D20: 2018 | E20: 2019 | F20: 2020/21 | G20: 2021/22 | H20: 2022/23
B21: Total schools | C21: 4719 | D21: 4571 | E21: 4706 | F21: 5144 | G21: 4842 | H21: 4923
B22: Preprimary | C22: 1031 | D22: 1037 | E22: 1102 | F22: 828 | G22: 387 | H22: 352
B23: Preprimary + Primary | C23: 1315 | D23: 1361 | E23: 1410 | F23: 1692 | G23: 2020 | H23: 2211
B24: Preprimary + Lower Secondary | G24: 1 | H24: 1
B25: Preprimary + Primary + Lower Secondary | C25: 443 | D25: 454 | E25: 486 | F25: 712 | G25: 733 | H25: 776
B26: Preprimary + Primary + Gen. Upper Secondary | G26: 1 | H26: 1
B27: Preprimary + Primary + TVET | G27: 2 | H27: 3
B28: Preprimary + Lower + Gen. Upper Secondary | G28: 4 | H28: 4
B29: Preprimary + Primary + Lower Secondary + TVET | G29: 29 | H29: 36
B30: Preprimary + Primary + Lower + Gen. Upper Secondary | C30: 397 | D30: 358 | E30: 403 | F30: 509 | G30: 584 | H30: 597
B31: Preprimary + Primary + Lower+ Gen. Upper Secondary + TVET | G31: 47 | H31: 67
B32: Preprimary+ TVET+ Accounting | H32: 1
B33: Preprimary + Primary + Lower Secondary + Upper Secondary + Accounting | H33: 2
B34: Primary | C34: 470 | D34: 439 | E34: 434 | F34: 447 | G34: 243 | H34: 132
B35: Primary + Lower Secondary | C35: 149 | D35: 161 | E35: 108 | F35: 196 | G35: 91 | H35: 51
B36: Primary + TVET | G36: 1 | H36: 0
B37: Primary + Lower Secondary + TVET + Accounting | H37: 1
B38: Primary + Lower + Gen. Upper Secondary | C38: 91 | D38: 134 | E38: 118 | F38: 132 | G38: 75 | H38: 48
B39: Primary + Lower Secondary + TVET | G39: 2 | H39: 3
B40: Primary + Lower + Gen. Upper Secondary + TVET | C40: 12 | D40: 2 | E40: 2 | F40: 3 | G40: 3 | H40: 4
B41: Lower Secondary | C41: 33 | D41: 24 | E41: 21 | F41: 20 | G41: 11 | H41: 13
B42: Lower + Gen. Upper Secondary | C42: 218 | D42: 225 | E42: 266 | F42: 240 | G42: 240 | H42: 230
B43: Lower Secondary + TVET | G43: 14 | H43: 16
B44: Lower Secondary + Gen. Upper Secondary + Accounting | H44: 2
...

Sheet LEARNERS
B2: 2. LEARNERS
B4: 2.1. Number of learners per school status
B6: Table 2.1.1: Number of total learners in Rwanda education system
B7: Indicator/Year | C7: 2017 | D7: 2018 | E7: 2019 | F7: 2020/21 | G7: 2021/22 | H7: 2022/23
B8: Total learners | C8: 3614004 | D8: 3619871 | E8: 3750252 | F8: 4029848 | G8: 4159782 | H8: 4456419
B9: Male | C9: 1783151 | D9: 1786491 | E9: 1854214 | F9: 1975737 | G9: 2050664 | H9: 2209396
B10: Female | C10: 1830853 | D10: 1833380 | E10: 1896038 | F10: 2054111 | G10: 2109118 | H10: 2247023
B11: % of Male | C11: 0.493 | D11: 0.494 | E11: 0.494 | F11: 0.49 | G11: 0.493 | H11: 0.496
B12: % of Female | C12: 0.507 | D12: 0.506 | E12: 0.506 | F12: 0.51 | G12: 0.507 | H12: 0.504
B13: Public schools | C13: 1098480 | D13: 1110454 | E13: 1171768 | F13: 1506280 | G13: 1590690 | H13: 1725647
B14: Male | C14: 546970 | D14: 556061 | E14: 588029 | F14: 745710 | G14: 792307 | H14: 862398
B15: Female | C15: 551510 | D15: 554393 | E15: 583739 | F15: 760570 | G15: 798383 | H15: 863249
B16: Government-subsidized schools | C16: 2149617 | D16: 2159576 | E16: 2189152 | F16: 2134012 | G16: 2169708 | H16: 2299765
B17: Male | C17: 1050577 | D17: 1056498 | E17: 1071594 | F17: 1036099 | G17: 1058085 | H17: 1129641
B18: Female | C18: 1099040 | D18: 1103078 | E18: 1117558 | F18: 1097913 | G18: 1111623 | H18: 1170124
B19: Private schools | C19: 365907 | D19: 349841 | E19: 389332 | F19: 389556 | G19: 399384 | H19: 431007
... B21: Female | C21: 180303 | D21: 175909 | E21: 194741 | F21: 195628 | G21: 199112 | H21: 213650
B22: Source: School census, Ministry of Education
B24: Table 2.1.2: Number of children in Early Childhood Developments (ECDs)
B25: Indicator/Year | C25: 2017 | D25: 2018 | E25: 2019 | F25: 2020/21 | G25: 2021/22 | H25: 2022/23
B26: Total children in ECDs | C26: 225669 | D26: 233197 | E26: 289118 | F26: 297021 | G26: 1033011 | H26: 1134913
B27: Male | C27: 110978 | D27: 115243 | E27: 142201 | F27: 144646 | G27: 496439 | H27: 548014
B28: Female | C28: 114691 | D28: 117954 | E28: 146917 | F28: 152375 | G28: 536572 | H28: 586899
B29: % of Male | C29: 0.492 | D29: 0.494 | E29: 0.492 | F29: 0.487 | G29: 0.481 | H29: 0.483
B30: % of Female | C30: 0.508 | D30: 0.506 | E30: 0.508 | F30: 0.513 | G30: 0.519 | H30: 0.517
B31: Total children in ECED centers | C31: 5234 | D31: 6491 | E31: 6690 | F31: 3198 | G31: 677686 | H31: 593915
B32: Male | C32: 2516 | D32: 3199 | E32: 3290 | F32: 1586 | G32: 318916 | H32: 276170
B33: Female | C33: 2718 | D33: 3292 | E33: 3400 | F33: 1612 | G33: 358770 | H33: 317745
B34: ECED children in Formal centers | C34: 5234 | D34: 6491 | E34: 6690 | F34: 3198 | G34: 25056 | H34: 24625
B35: Male | C35: 2516 | D35: 3199 | E35: 3290 | F35: 1586 | G35: 11784 | H35: 11557
B36: Female | C36: 2718 | D36: 3292 | E36: 3400 | F36: 1612 | G36: 13272 | H36: 13068
B37: ECED children in non-formal centers* | G37: 652630 | H37: 569290
B38: Male | G38: 307132 | H38: 264613
B39: Female | G39: 345498 | H39: 304677
B40: Total pupils in Preprimary level | C40: 220435 | D40: 226706 | E40: 282428 | F40: 293823 | G40: 355325 | H40: 540998
B41: Male | C41: 108462 | D41: 112044 | E41: 138911 | F41: 143060 | G41: 177523 | H41: 271844
B42: Female | C42: 111973 | D42: 114662 | E42: 143517 | F42: 150763 | G42: 177802 | H42: 269154
B43: Female
B45: Table 2.1.3: Number of preprimary pupils
B46: Indicator/Year | C46: 2017 | D46: 2018 | E46: 2019 | F46: 2020/21 | G46: 2021/22 | H46: 2022/23
...

Sheet SCHOOL  STAFF
B2: 3. SCHOOL STAFF
B4: 3.1 School staff per school status
B6: Table 3.1.1: Number of total school staff in Rwanda education system
B7: Description/Year | C7: 2017 | D7: 2018 | E7: 2019 | F7: 2020/21 | G7: 2021/22 | H7: 2022/23
B8: Total school staff | C8: 93691 | D8: 94437 | E8: 97731 | F8: 121145 | G8: 125621 | H8: 138038
B9: Male | C9: 51422 | D9: 51403 | E9: 52435 | F9: 61545 | G9: 64414 | H9: 70430
B10: Female | C10: 42269 | D10: 43034 | E10: 45296 | F10: 59600 | G10: 61207 | H10: 67608
B11: %Male | C11: 0.549 | D11: 0.544 | E11: 0.537 | F11: 0.508 | G11: 0.513 | H11: 0.51022182
B12: %Female | C12: 0.451 | D12: 0.456 | E12: 0.463 | F12: 0.492 | G12: 0.487 | H12: 0.48977818
B13: Staff in Public schools | C13: 27125 | D13: 27392 | E13: 28454 | F13: 42522 | G13: 45849 | H13: 50287
B14: Male | C14: 15687 | D14: 15788 | E14: 16144 | F14: 22045 | G14: 23893 | H14: 26035
B15: Female | C15: 11438 | D15: 11604 | E15: 12310 | F15: 20477 | G15: 21956 | H15: 24252
B16: Staff in Government-subsidized schools | C16: 47698 | D16: 48568 | E16: 49345 | F16: 58576 | G16: 61463 | H16: 66567
B17: Male | C17: 24545 | D17: 24730 | E17: 24803 | F17: 27970 | G17: 29814 | H17: 32045
B18: Female | C18: 23153 | D18: 23838 | E18: 24542 | F18: 30606 | G18: 31649 | H18: 34522
B19: Staff in Private schools | C19: 18868 | D19: 18477 | E19: 19932 | F19: 20047 | G19: 18309 | H19: 21184
... B21: Female | C21: 7678 | D21: 7592 | E21: 8444 | F21: 8517 | G21: 7602 | H21: 8834
B22: Source: School census, Ministry of Education
B24: Table 3.1.2: Number of total school staff in Preprimary, Primary, Secondary and TVET L1-L5
B25: Description/Year | C25: 2017 | D25: 2018 | E25: 2019 | F25: 2020/21 | G25: 2021/22 | H25: 2022/23
B26: Total school staff | C26: 81133 | D26: 82030 | E26: 84969 | F26: 109178 | G26: 113288 | H26: 125462
B27: Male | C27: 42764 | D27: 42823 | E27: 43710 | F27: 53356 | G27: 56181 | H27: 62016
B28: Female | C28: 38369 | D28: 39207 | E28: 41259 | F28: 55822 | G28: 57107 | H28: 63446
B29: %Male | C29: 0.527 | D29: 0.522 | E29: 0.514 | F29: 0.489 | G29: 0.496 | H29: 0.494
B30: %Female | C30: 0.473 | D30: 0.478 | E30: 0.486 | F30: 0.511 | G30: 0.504 | H30: 0.506
B31: Staff in Public schools | C31: 22429 | D31: 22545 | E31: 23696 | F31: 37076 | G31: 40310 | H31: 44842
B32: Male | C32: 12476 | D32: 12462 | E32: 12875 | F32: 18354 | G32: 20266 | H32: 22501
B33: Female | C33: 9953 | D33: 10083 | E33: 10821 | F33: 18722 | G33: 20044 | H33: 22341
B34: Staff in Government-subsidized schools | C34: 44595 | D34: 45238 | E34: 46109 | F34: 55469 | G34: 58090 | H34: 63248
B35: Male | C35: 22526 | D35: 22557 | E35: 22716 | F35: 25994 | G35: 27702 | H35: 29918
B36: Female | C36: 22069 | D36: 22681 | E36: 23393 | F36: 29475 | G36: 30388 | H36: 33330
B37: Staff in Private schools | C37: 14109 | D37: 14247 | E37: 15164 | F37: 16633 | G37: 14888 | H37: 17372
... B39: Female | C39: 6347 | D39: 6443 | E39: 7045 | F39: 7625 | G39: 6675 | H39: 7775
B40: Source: School census, Ministry of Education
B42: Table 3.1.3: Number of Higher education staff
B43: Indicator/Year | C43: 2016/17 | D43: 2017/18 | E43: 2018/19 | F43: 2020/21 | G43: 2021/22 | H43: 2022/23
B44: Total staff | C44: 6271 | D44: 6335 | E44: 6610 | F44: 6065 | G44: 6250 | H44: 6759
B45: Male | C45: 4652 | D45: 4758 | E45: 4921 | F45: 4577 | G45: 4665 | H45: 4992
B46: Female | C46: 1619 | D46: 1577 | E46: 1689 | F46: 1488 | G46: 1585 | H46: 1767
B47: % of Male | C47: 0.742 | D47: 0.751 | E47: 0.744 | F47: 0.755 | G47: 0.746 | H47: 0.73857079
...

Sheet ICT, SCIENCE AND TECHNOLOGY
B2: 4. ICT, SCIENCE AND TECHNOLOGY
B4: 4.1 Use of ICT in schools
B6: Table 4.1.1: Use of ICT for teaching and learning
B7: Level of education | C7: 2017 | D7: 2018 | E7: 2019 | F7: 2020/21 | G7: 2021/22 | H7: 2022/23
B8: Overall number of schools using ICT for teaching and learning | C8: 1649 | D8: 1796 | E8: 1852 | F8: 1929 | G8: 2286 | H8: 2021
B9: Schools with Preprimary level | C9: 160 | D9: 228 | E9: 278 | F9: 426 | G9: 1677 | H9: 1575
B10: Schools with Primary level | C10: 1267 | D10: 1612 | E10: 1718 | F10: 1710 | G10: 1790 | H10: 1622
B11: Schools with Gen. and prof. Secondary level | C11: 854 | D11: 886 | E11: 951 | F11: 1116 | G11: 1201 | H11: 1076
B12: Schools with TVET L1-L5 levels | C12: 90 | D12: 232 | E12: 236 | F12: 240 | G12: 250 | H12: 226
B13: Overall number of schools not using ICT for teaching and learning | C13: 3070 | D13: 2776 | E13: 2854 | F13: 3215 | G13: 2556 | H13: 2902
B14: Schools with Preprimary level | C14: 3026 | D14: 2982 | E14: 3123 | F14: 3315 | G14: 2131 | H14: 2476
B15: Schools with Primary level | C15: 1610 | D15: 1297 | E15: 1243 | F15: 1981 | G15: 2041 | H15: 2310
B16: Schools with Gen. and prof. Secondary level | C16: 713 | D16: 530 | E16: 501 | F16: 753 | G16: 754 | H16: 901
B17: Schools with TVET L1-L5 levels | C17: 295 | D17: 118 | E17: 95 | F17: 104 | G17: 172 | H17: 244
B18: Percentage of schools using ICT for teaching and learning | C18: 0.349 | D18: 0.393 | E18: 0.393 | F18: 0.375 | G18: 0.472 | H18: 0.411
B19: Schools with Preprimary level | C19: 0.05 | D19: 0.071 | E19: 0.082 | F19: 0.114 | G19: 0.44 | H19: 0.389
... B22: Schools with TVET L1-L5 levels | C22: 0.234 | D22: 0.663 | E22: 0.713 | F22: 0.698 | G22: 0.592 | H22: 0.481
B23: Source: School census, Ministry of Education
B25: 4.2 ICT, Science, and Technology facilities
B27: Table 4.2.1: Smart classrooms in schools
B28: Level of education | C28: 2020/21 | D28: 2021/22 | E28: 2022/23
B29: Overall number of schools with smart classroom | C29: 957 | D29: 1120 | E29: 1081
B30: Schools with Primary level | C30: 373 | D30: 777 | E30: 767
B31: Schools with Gen. and prof. Secondary level | C31: 831 | D31: 885 | E31: 854
B32: Schools with TVET L1-L5 levels | C32: 123 | D32: 152 | E32: 157
B33: Overall number of schools without smart classroom | C33: 3359 | D33: 3722 | E33: 3842
B34: Schools with Primary level | C34: 3318 | D34: 3054 | E34: 3165
B35: Schools with Gen. and prof. Secondary level | C35: 1038 | D35: 1070 | E35: 1123
B36: Schools with TVET L1-L5 levels | C36: 221 | D36: 270 | E36: 313
B37: Percentage of schools with smart classroom | C37: 0.222 | D37: 0.231 | E37: 0.22
B38: % of Schools with Primary level | C38: 0.101 | D38: 0.203 | E38: 0.195
B39: % Schools with Gen. and prof. Secondary level | C39: 0.445 | D39: 0.453 | E39: 0.432
B40: % Schools with TVET L1-L5 levels | C40: 0.358 | D40: 0.36 | E40: 0.334
B41: Source: School census, Ministry of Education
B43: Table 4.2.2: Computer laboratories in schools
B44: Level of education | C44: 2020/21 | D44: 2021/22 | E44: 2022/23
B45: Overall number of schools with Computer laboratories | C45: 1004 | D45: 1302 | E45: 1373
B46: Schools with Primary level | C46: 337 | D46: 824 | E46: 875
B47: Schools with Gen. and prof. Secondary level | C47: 433 | D47: 778 | E47: 815
B48: Schools with TVET L1-L5 levels | C48: 239 | D48: 297 | E48: 325
...

Sheet BOOKS AND TEXTBOOKS
B2: 5. BOOKS AND TEXTBOOKS
B4: 5.1 Books in use by learners
B6: Table 5.1.1: Students books in preprimary schools by subject
B7: Subjects | C7: 2018 | D7: 2019 | E7: 2020/21 | F7: 2021/22 | G7: 2022/23
B8: Number of books
B9: Discovery of the World | C9: 19245 | D9: 22887 | E9: 23629 | F9: 28101 | G9: 31215
B10: Numeracy | C10: 26359 | D10: 27974 | E10: 27173 | F10: 28838 | G10: 30134
B11: Physical and Health development | C11: 13785 | D11: 15966 | E11: 17071 | F11: 19772 | G11: 22020
B12: Creative arts and Culture | C12: 16324 | D12: 18035 | E12: 17507 | F12: 19342 | G12: 20639
B13: Language and literacy: Kinyarwanda | C13: 36879 | D13: 37472 | E13: 35291 | F13: 35858 | G13: 37190
B14: Language and literacy: English | C14: 29196 | D14: 27876 | E14: 27862 | F14: 29122 | G14: 29773
B15: Average ratio per level | C15: 11 | D15: 12 | E15: 13 | F15: 14 | G15: 20
B16: Discovery of the World | C16: 12 | D16: 12 | E16: 12 | F16: 13 | G16: 17
B17: Numeracy | C17: 9 | D17: 10 | E17: 11 | F17: 12 | G17: 18
B18: Physical and Health development | C18: 16 | D18: 18 | E18: 17 | F18: 18 | G18: 25
B19: Creative arts and Culture | C19: 14 | D19: 16 | E19: 17 | F19: 18 | G19: 26
B20: Language and literacy: Kinyarwanda | C20: 6 | D20: 8 | E20: 8 | F20: 10 | G20: 15
B21: Language and literacy: English | C21: 8 | D21: 10 | E21: 11 | F21: 12 | G21: 18
B22: Source: School census, Ministry of Education
B24: Table 5.1.2: Books in use by primary students by subject
B25: Subject | C25: 2018 | D25: 2019 | E25: 2020/21 | F25: 2021/22 | G25: 2022/23
B26: Number of books
B27: Kinyarwanda | C27: 1794444 | D27: 1614643 | E27: 1894875 | F27: 2223743 | G27: 2446559
B28: English | C28: 2039752 | D28: 1778664 | E28: 2302863 | F28: 2981551 | G28: 3363189
B29: Mathematics | C29: 1318615 | D29: 1152290 | E29: 1691881 | F29: 2484150 | G29: 2797491
B30: Social and Religious Studies | C30: 993068 | D30: 886472 | E30: 796930 | F30: 877427 | G30: 971610
B31: Elementary Science and Technology | C31: 635757 | D31: 601190 | E31: 594340 | F31: 601112 | G31: 633795
B32: Average ratio per level | C32: 2 | D32: 2 | E32: 2 | F32: 2 | G32: 2
B33: Kinyarwanda | C33: 1 | D33: 2 | E33: 1 | F33: 1 | G33: 1
B34: English | C34: 1 | D34: 1 | E34: 1 | F34: 1 | G34: 1
B35: Mathematics | C35: 2 | D35: 2 | E35: 2 | F35: 1 | G35: 1
B36: Social and Religious Studies | C36: 3 | D36: 3 | E36: 3 | F36: 3 | G36: 3
B37: Elementary Science and Technology | C37: 4 | D37: 4 | E37: 5 | F37: 5 | G37: 4
B38: Source: School census, Ministry of Education
B40: Table 5.1.3: Pupil: book ratio in lower secondary students by subject
B41: Subjects | C41: 2018 | D41: 2019 | E41: 2020/21 | F41: 2021/22 | G41: 2022/23
B42: Number of books
B43: Mathematics | C43: 255498 | D43: 254984 | E43: 233758 | F43: 243723 | G43: 283000
B44: Chemistry | C44: 235334 | D44: 226974 | E44: 214614 | F44: 224269 | G44: 265851
B45: Geography | C45: 223978 | D45: 217380 | E45: 195869 | F45: 203548 | G45: 231170
...

Sheet ENERGY,WATER, AND SANITATION
B2: 6. ENERGY, WATER AND SANITATION
B4: 6.1 On grid electricity
B6: Table 6.1.1: On grid electricity in schools
B7: ON GRID ELECTRICITY | C7: 2017 | D7: 2018 | E7: 2019 | F7: 2020/21 | G7: 2021/22 | H7: 2022/23
B8: Overall number of schools with | C8: 2284 | D8: 2784 | E8: 3074 | F8: 3819 | G8: 3916 | H8: 3973
B9: Schools with Preprimary level | C9: 1030 | D9: 1277 | E9: 1356 | F9: 2147 | G9: 3016 | H9: 3174
B10: Schools with Primary level | C10: 1606 | D10: 1693 | E10: 1800 | F10: 2460 | G10: 2995 | H10: 3057
B11: Schools with Gen. and prof. Secondary level | C11: 940 | D11: 1027 | E11: 1078 | F11: 1456 | G11: 1715 | H11: 1718
B12: Schools with TVET L1-L5 levels | C12: 175 | D12: 256 | E12: 286 | F12: 327 | G12: 407 | H12: 451
B13: Overall number of schools without | C13: 2435 | D13: 1787 | E13: 1632 | F13: 1325 | G13: 926 | H13: 950
B14: Schools with Preprimary level | C14: 2156 | D14: 1933 | E14: 2045 | F14: 1594 | G14: 792 | H14: 877
B15: Schools with Primary level | C15: 1271 | D15: 1216 | E15: 1161 | F15: 1231 | G15: 836 | H15: 875
B16: Schools with Gen. and prof. Secondary level | C16: 627 | D16: 389 | E16: 374 | F16: 413 | G16: 240 | H16: 259
B17: Schools with TVET L1-L5 levels | C17: 210 | D17: 94 | E17: 45 | F17: 17 | G17: 15 | H17: 19
B18: Percentage of schools with | C18: 0.484 | D18: 0.609 | E18: 0.653 | F18: 0.743 | G18: 0.809 | H18: 0.807
B19: Schools with Preprimary level | C19: 0.323 | D19: 0.398 | E19: 0.399 | F19: 0.574 | G19: 0.792 | H19: 0.784
... B22: Schools with TVET L1-L5 levels | C22: 0.455 | D22: 0.731 | E22: 0.864 | F22: 0.951 | G22: 0.888 | H22: 0.881
B23: Source: School census, Ministry of Education
B25: 6.2 Off grid electricity
B27: Table 6.2.1: Solar power in schools
B28: SOLAR POWER | C28: 2017 | D28: 2018 | E28: 2019 | F28: 2020/21 | G28: 2021/22 | H28: 2022/23
B29: Overall number of schools with | C29: 638 | D29: 664 | E29: 626 | F29: 758 | G29: 1589 | H29: 1012
B30: Schools with Preprimary level | C30: 177 | D30: 191 | E30: 201 | F30: 356 | G30: 1299 | H30: 887
B31: Schools with Primary level | C31: 709 | D31: 605 | E31: 562 | F31: 694 | G31: 1365 | H31: 900
B32: Schools with Gen. and prof. Secondary level | C32: 281 | D32: 274 | E32: 267 | F32: 349 | G32: 752 | H32: 484
B33: Schools with TVET L1-L5 levels | C33: 23 | D33: 42 | E33: 33 | F33: 41 | G33: 115 | H33: 73
B34: Overall number of schools without | C34: 4081 | D34: 3907 | E34: 4080 | F34: 4386 | G34: 3253 | H34: 3911
B35: Schools with Preprimary level | C35: 3009 | D35: 3019 | E35: 3200 | F35: 3385 | G35: 2509 | H35: 3164
B36: Schools with Primary level | C36: 2168 | D36: 2304 | E36: 2399 | F36: 2997 | G36: 2466 | H36: 3032
B37: Schools with Gen. and prof. Secondary level | C37: 1286 | D37: 1142 | E37: 1185 | F37: 1520 | G37: 1203 | H37: 1493
B38: Schools with TVET L1-L5 levels | C38: 362 | D38: 308 | E38: 298 | F38: 303 | G38: 307 | H38: 397
B39: Percentage of schools with | C39: 0.135 | D39: 0.145 | E39: 0.133 | F39: 0.147 | G39: 0.328 | H39: 0.206
B40: Schools with Preprimary level | C40: 0.056 | D40: 0.06 | E40: 0.059 | F40: 0.095 | G40: 0.341 | H40: 0.219
... B43: Schools with TVET L1-L5 levels | C43: 0.06 | D43: 0.12 | E43: 0.1 | F43: 0.119 | G43: 0.273 | H43: 0.155
B44: Source: School census, Ministry of Education
B46: Table 6.2.2: Electric power generator in schools
B47: ELECTRIC POWER GENERATOR | C47: 2017 | D47: 2018 | E47: 2019 | F47: 2020/21 | G47: 2021/22 | H47: 2022/23
B48: Overall number of schools with | C48: 545 | D48: 842 | E48: 885 | F48: 762 | G48: 1282 | H48: 646
B49: Schools with Preprimary level | C49: 78 | D49: 120 | E49: 124 | F49: 144 | G49: 832 | H49: 310
B50: Schools with Primary level | C50: 138 | D50: 159 | E50: 169 | F50: 144 | G50: 850 | H50: 301
...

Sheet SCHOOL NUTRITION
B2: 7. SCHOOL NUTRITION
B4: 7.1 Learners fed at school
B6: Table 7.1.1: Number of learners fed at schools
B7: Levels of education | C7: 2017 | D7: 2018 | E7: 2019 | F7: 2020/21 | G7: 2021/22 | H7: 2022/23
B8: Total number of students fed at school | C8: 610630 | D8: 724059 | E8: 796256 | F8: 874244 | G8: 3375454 | H8: 3908597
B9: Preprimary | C9: 33944 | D9: 49401 | E9: 52509 | F9: 52787 | G9: 250306 | H9: 496478
B10: Primary | C10: 183310 | D10: 183857 | E10: 182678 | F10: 309419 | G10: 2421231 | H10: 2624481
B11: Gen. and prof. Secondary level | C11: 357329 | D11: 444578 | E11: 520480 | F11: 468493 | G11: 653185 | H11: 710799
B12: TVET | C12: 36047 | D12: 46223 | E12: 40589 | F12: 43545 | G12: 50732 | H12: 76839
B13: Percentage of students fed at school | C13: 0.182 | D13: 0.214 | E13: 0.226 | F13: 0.23 | G13: 0.863 | H13: 0.928
B14: Preprimary | C14: 0.154 | D14: 0.218 | E14: 0.186 | F14: 0.18 | G14: 0.704 | H14: 0.918
B15: Primary | C15: 0.072 | D15: 0.073 | E15: 0.073 | F15: 0.113 | G15: 0.883 | H15: 0.925
B16: Gen. and prof. Secondary level | C16: 0.697 | D16: 0.768 | E16: 0.802 | F16: 0.675 | G16: 0.894 | H16: 0.974
B17: TVET | C17: 0.453 | D17: 0.582 | E17: 0.514 | F17: 0.495 | G17: 0.608 | H17: 0.742
B18: Source: School census, Ministry of Education
B20: Table 7.1.2: Number of learners fed at schools By school status
B22: School year | C22: 2022/23
B23: Total number Students | C23: 4212893
B24: Public | C24: 1636011
B25: Government-subsidized | C25: 2243125
B26: Private | C26: 333757
B27: Total number Students fed at schools | C27: 3908597
B28: Public | C28: 1596542
B29: Government-subsidized | C29: 2200534
B30: Private | C30: 111521
B31: Percentage of Students fed at schools | C31: 0.928
B32: Public | C32: 0.976
B33: Government-subsidized | C33: 0.981
B34: Private | C34: 0.334
B35: Source: School census, Ministry of Education
B38: 7.2 School nutrition facilities and equipment
B40: Table 7.2.1: Number of schools providing meals to students
B41: Levels of education | C41: 2017 | D41: 2018 | E41: 2019 | F41: 2020/21 | G41: 2021/22 | H41: 2022/23
B42: Number of schools providing meals to students | C42: 1648 | D42: 1808 | E42: 2189 | F42: 3093 | G42: 3978 | H42: 4305
B43: Schools with Preprimary level | C43: 379 | D43: 625 | E43: 1277 | F43: 1300 | G43: 3108 | H43: 3464
B44: Schools with Primary level | C44: 357 | D44: 372 | E44: 504 | F44: 1443 | G44: 3385 | H44: 3602
B45: Schools with Gen. and prof. Secondary level | C45: 1181 | D45: 1196 | E45: 1236 | F45: 1740 | G45: 1828 | H45: 1847
B46: Schools with TVET L1-L5 levels | C46: 154 | D46: 145 | E46: 154 | F46: 253 | G46: 299 | H46: 371
B47: Number of schools not providing meals to students | C47: 3071 | D47: 2763 | E47: 2517 | F47: 2051 | G47: 864 | H47: 618
B48: Schools with Preprimary level | C48: 2807 | D48: 2585 | E48: 2124 | F48: 2441 | G48: 700 | H48: 587
...

Sheet SPECIAL NEEDS EDUCATION
B2: 8. SPECIAL NEEDS EDUCATION
B4: 8.1 Adapted facilities for learners with special needs
B6: Table 8.1.1: Adapted infrastructure and materials for learners with disability
B7: Levels of education | C7: 2017 | D7: 2018 | E7: 2019 | F7: 2020/21 | G7: 2021/22 | H7: 2022/23
B8: Overall number of schools with | C8: 764 | D8: 1010 | E8: 1434 | F8: 2115 | G8: 3301 | H8: 3344
B9: Schools with Preprimary level | C9: 183 | D9: 264 | E9: 356 | F9: 580 | G9: 2563 | H9: 2730
B10: Schools with Primary level | C10: 522 | D10: 684 | E10: 686 | F10: 1390 | G10: 2666 | H10: 2710
B11: Schools with Gen. and prof. Secondary level | C11: 280 | D11: 393 | E11: 443 | F11: 815 | G11: 1428 | H11: 1419
B12: Schools with TVET L1-L5 levels | C12: 89 | D12: 101 | E12: 191 | F12: 233 | G12: 300 | H12: 331
B13: Overall number of schools without | C13: 3955 | D13: 3561 | E13: 3272 | F13: 3029 | G13: 1541 | H13: 1498
B14: Schools with Preprimary level | C14: 3003 | D14: 2946 | E14: 3045 | F14: 3161 | G14: 1245 | H14: 1078
B15: Schools with Primary level | C15: 2355 | D15: 2225 | E15: 2275 | F15: 2301 | G15: 1165 | H15: 1121
B16: Schools with Gen. and prof. Secondary level | C16: 1287 | D16: 1023 | E16: 1009 | F16: 1054 | G16: 530 | H16: 539
B17: Schools with TVET L1-L5 levels | C17: 296 | D17: 249 | E17: 140 | F17: 111 | G17: 122 | H17: 91
B18: Percentage of schools with | C18: 0.162 | D18: 0.221 | E18: 0.305 | F18: 0.411 | G18: 0.682 | H18: 0.691
B19: Schools with Preprimary level | C19: 0.057 | D19: 0.082 | E19: 0.105 | F19: 0.155 | G19: 0.673 | H19: 0.717
... B22: Schools with TVET L1-L5 levels | C22: 0.231 | D22: 0.289 | E22: 0.577 | F22: 0.677 | G22: 0.711 | H22: 0.784
B23: Source: School census, Ministry of Education
B25: Table 8.1.2: Accessible toilets for people with disability
B26: Levels of education | C26: Public | D26: Government subsidized | E26: Private | F26: Total
B27: Overall number of schools with | C27: 880 | D27: 1,062 | E27: 301 | F27: 2243
B28: Schools with Preprimary level | C28: 712 | D28: 957 | E28: 237 | F28: 1906 | G28: =F28+F29 -> 3891
B29: Schools with Primary level | C29: 778 | D29: 1,014 | E29: 193 | F29: 1985
B30: Schools with Gen. and prof. Secondary level | C30: 393 | D30: 547 | E30: 37 | F30: 977
B31: Schools with TVET L1-L5 levels | C31: 87 | D31: 44 | E31: 44 | F31: 175
B32: Overall number of schools without | C32: 688 | D32: 1,003 | E32: 989 | F32: 2680
B33: Schools with Preprimary level | C33: 531 | D33: 838 | E33: 776 | F33: 2145
B34: Schools with Primary level | C34: 548 | D34: 877 | E34: 522 | F34: 1947
B35: Schools with Gen. and prof. Secondary level | C35: 336 | D35: 522 | E35: 142 | F35: 1000
B36: Schools with TVET L1-L5 levels | C36: 81 | D36: 65 | E36: 149 | F36: 295
B37: Percentage of schools with | C37: 56.1% | D37: 51.4% | E37: 23.3% | F37: 0.456
B38: Schools with Preprimary level | C38: 57.3% | D38: 53.3% | E38: 23.4% | F38: 0.471
B39: Schools with Primary level | C39: 58.7% | D39: 53.6% | E39: 27.0% | F39: 0.505
B40: Schools with Gen. and prof. Secondary level | C40: 53.9% | D40: 51.2% | E40: 20.7% | F40: 0.494
B41: Schools with TVET L1-L5 levels | C41: 51.8% | D41: 40.4% | E41: 22.8% | F41: 0.372
B42: Source: School census, Ministry of Education
B45: 8.2 Staff trained in special needs and inclusive education.
B47: Table 8.2.1: Total schools Staff trained in special needs and inclusive education.
B48: Indicator/Year | C48: 2017 | D48: 2018 | E48: 2019 | F48: 2020/21 | G48: 2021/22 | H48: 2022/23
B49: Total staff trained in SNE | C49: 3398 | D49: 6734 | E49: 7730 | F49: 12243 | G49: 15569 | H49: 16412
...

Sheet ANNEXES
B2: ANNEX
B4: Annex 1: Number of schools with Preprimary level by district
B5: District/Province | C5: 2021/22 | D5: 2022/23
B6: Gisagara | C6: 91 | D6: 93
B7: Huye | C7: 107 | D7: 110
B8: Kamonyi | C8: 149 | D8: 150
B9: Muhanga | C9: 149 | D9: 150
B10: Nyamagabe | C10: 109 | D10: 126
B11: Nyanza | C11: 103 | D11: 104
B12: Nyaruguru | C12: 102 | D12: 102
B13: Ruhango | C13: 96 | D13: 99
B14: South | C14: 906 | D14: 934
B15: Karongi | C15: 151 | D15: 156
B16: Ngororero | C16: 115 | D16: 116
B17: Nyabihu | C17: 98 | D17: 100
... B41: Rwanda | C41: 3808 | D41: 4051
B42: Source: School census, Ministry of Education
B44: Annex 2: Number of schools with Primary level by district
B45: District/Province | C45: 2021/22 | D45: 2022/23
B46: Gisagara | C46: 95 | D46: 95
B47: Huye | C47: 111 | D47: 112
B48: Kamonyi | C48: 142 | D48: 144
B49: Muhanga | C49: 138 | D49: 140
B50: Nyamagabe | C50: 134 | D50: 135
B51: Nyanza | C51: 99 | D51: 100
B52: Nyaruguru | C52: 102 | D52: 102
B53: Ruhango | C53: 97 | D53: 97
B54: South | C54: 918 | D54: 925
B55: Karongi | C55: 153 | D55: 156
B56: Ngororero | C56: 116 | D56: 116
B57: Nyabihu | C57: 100 | D57: 102
... B81: Rwanda | C81: 3831 | D81: 3932
B82: Source: School census, Ministry of Education
B84: Annex 3: Number of schools with general & professional secondary level by district
B85: District/Province | C85: 2021/22 | D85: 2022/23
B86: Gisagara | C86: 53 | D86: 55
B87: Huye | C87: 51 | D87: 51
B88: Kamonyi | C88: 70 | D88: 70
B89: Muhanga | C89: 65 | D89: 65
B90: Nyamagabe | C90: 60 | D90: 60
...
